# ./tests/diskless drbd-test-sp2-manually-1 drbd-test-sp2-manually-2 drbd-test-sp2-manually-3
Logging to directory log/diskless-20160811-135057
drbd-test-sp2-manually-1: iptables: Chain already exists.
drbd-test-sp2-manually-1: iptables: Chain already exists.
drbd-test-sp2-manually-2: iptables: Chain already exists.
drbd-test-sp2-manually-2: iptables: Chain already exists.
drbd-test-sp2-manually-3: iptables: Chain already exists.
drbd-test-sp2-manually-3: iptables: Chain already exists.
drbd-test-sp2-manually-1: drbdsetup new-resource diskless-20160811-135057 0 
drbd-test-sp2-manually-1: drbdsetup new-minor diskless-20160811-135057 138 0 
drbd-test-sp2-manually-1: drbdmeta 138 v09 /dev/scratch/diskless-20160811-135057-disk0 internal apply-al 
drbd-test-sp2-manually-1: drbdsetup attach 138 /dev/scratch/diskless-20160811-135057-disk0 /dev/scratch/diskless-20160811-135057-disk0 internal --md-flushes=no --disk-flushes=no 
drbd-test-sp2-manually-1: drbdsetup new-peer diskless-20160811-135057 1 --_name=drbd-test-sp2-manually-2 
drbd-test-sp2-manually-1: drbdsetup new-path diskless-20160811-135057 1 ipv4:192.168.122.81:7789 ipv4:192.168.122.110:7789 
drbd-test-sp2-manually-1: drbdsetup new-peer diskless-20160811-135057 2 --_name=drbd-test-sp2-manually-3 
drbd-test-sp2-manually-1: drbdsetup new-path diskless-20160811-135057 2 ipv4:192.168.122.81:7789 ipv4:192.168.122.4:7789 
drbd-test-sp2-manually-1: drbdsetup connect diskless-20160811-135057 1 
drbd-test-sp2-manually-1: drbdsetup connect diskless-20160811-135057 2 
drbd-test-sp2-manually-2: drbdsetup new-resource diskless-20160811-135057 1 
drbd-test-sp2-manually-2: drbdsetup new-minor diskless-20160811-135057 138 0 
drbd-test-sp2-manually-2: drbdmeta 138 v09 /dev/scratch/diskless-20160811-135057-disk0 internal apply-al 
drbd-test-sp2-manually-2: drbdsetup attach 138 /dev/scratch/diskless-20160811-135057-disk0 /dev/scratch/diskless-20160811-135057-disk0 internal --md-flushes=no --disk-flushes=no 
drbd-test-sp2-manually-2: drbdsetup new-peer diskless-20160811-135057 0 --_name=drbd-test-sp2-manually-1 
drbd-test-sp2-manually-2: drbdsetup new-path diskless-20160811-135057 0 ipv4:192.168.122.110:7789 ipv4:192.168.122.81:7789 
drbd-test-sp2-manually-2: drbdsetup new-peer diskless-20160811-135057 2 --_name=drbd-test-sp2-manually-3 
drbd-test-sp2-manually-2: drbdsetup new-path diskless-20160811-135057 2 ipv4:192.168.122.110:7789 ipv4:192.168.122.4:7789 
drbd-test-sp2-manually-2: drbdsetup connect diskless-20160811-135057 0 
drbd-test-sp2-manually-2: drbdsetup connect diskless-20160811-135057 2 
drbd-test-sp2-manually-3: drbdsetup new-resource diskless-20160811-135057 2 
drbd-test-sp2-manually-3: drbdsetup new-minor diskless-20160811-135057 138 0 
drbd-test-sp2-manually-3: drbdsetup new-peer diskless-20160811-135057 0 --_name=drbd-test-sp2-manually-1 
drbd-test-sp2-manually-3: drbdsetup new-path diskless-20160811-135057 0 ipv4:192.168.122.4:7789 ipv4:192.168.122.81:7789 
drbd-test-sp2-manually-3: drbdsetup new-peer diskless-20160811-135057 1 --_name=drbd-test-sp2-manually-2 
drbd-test-sp2-manually-3: drbdsetup new-path diskless-20160811-135057 1 ipv4:192.168.122.4:7789 ipv4:192.168.122.110:7789 
drbd-test-sp2-manually-3: drbdsetup connect diskless-20160811-135057 0 
drbd-test-sp2-manually-3: drbdsetup connect diskless-20160811-135057 1 

drbd-test-sp2-manually-1: drbdsetup peer-device-options diskless-20160811-135057 1 0 
drbd-test-sp2-manually-1: drbdsetup peer-device-options diskless-20160811-135057 2 0 
drbd-test-sp2-manually-2: drbdsetup peer-device-options diskless-20160811-135057 0 0 
drbd-test-sp2-manually-2: drbdsetup peer-device-options diskless-20160811-135057 2 0 
drbd-test-sp2-manually-3: drbdsetup peer-device-options diskless-20160811-135057 0 0 
drbd-test-sp2-manually-3: drbdsetup peer-device-options diskless-20160811-135057 1 0 
Timeout waiting for patterns to match
Pattern 'peer-device .* peer-disk:UpToDate' does not match in drbd-test-sp2-manually-3:drbd-test-sp2-manually-2:0 (lines 17-20)
Traceback (most recent call last):
  File "./tests/diskless", line 23, in <module>
    resource.skip_initial_sync();
  File "/drbdtest/drbd-test.git/tests/python/drbdtest.py", line 659, in skip_initial_sync
    self.initial_resync(node)
  File "/drbdtest/drbd-test.git/tests/python/drbdtest.py", line 707, in initial_resync
    pds.event(r'peer-device .* peer-disk:UpToDate', timeout=300)
  File "/drbdtest/drbd-test.git/tests/python/drbdtest.py", line 471, in event
    resource.logscan(self, where, *args, **kwargs)
  File "/drbdtest/drbd-test.git/tests/python/drbdtest.py", line 577, in logscan
    result = subprocess.check_output(cmd + where)
  File "/usr/lib64/python2.7/subprocess.py", line 573, in check_output
    raise CalledProcessError(retcode, cmd, output=output)
subprocess.CalledProcessError: Command '['logscan', '-d', 'log/diskless-20160811-135057', '-w', '--timeout', '300', '-N', 'connection:Timeout', '-N', 'connection:ProtocolError', '-N', 'disk:Failed', '-N', 'peer-disk:Failed', '-N', 'connection:BrokenPipe', '-N', 'connection:NetworkFailure', '-y', 'peer-device .* peer-disk:UpToDate', 'events-drbd-test-sp2-manually-3', '--label', 'drbd-test-sp2-manually-3:drbd-test-sp2-manually-1:0', '-p', '.events-peer-device-drbd-test-sp2-manually-1:0.pos', '-f', 'peer-node-id:0', '-f', 'volume:0', 'events-drbd-test-sp2-manually-3', '--label', 'drbd-test-sp2-manually-3:drbd-test-sp2-manually-2:0', '-p', '.events-peer-device-drbd-test-sp2-manually-2:0.pos', '-f', 'peer-node-id:1', '-f', 'volume:0', 'events-drbd-test-sp2-manually-1', '--label', 'drbd-test-sp2-manually-1:drbd-test-sp2-manually-2:0', '-p', '.events-peer-device-drbd-test-sp2-manually-2:0.pos', '-f', 'peer-node-id:1', '-f', 'volume:0', 'events-drbd-test-sp2-manually-2', '--label', 'drbd-test-sp2-manually-2:drbd-test-sp2-manually-1:0', '-p', '.events-peer-device-drbd-test-sp2-manually-1:0.pos', '-f', 'peer-node-id:0', '-f', 'volume:0']' returned non-zero exit status 1
----------------------------------------
Exception happened during processing of request from ('192.168.122.81', 53618)
Traceback (most recent call last):
  File "/usr/lib64/python2.7/SocketServer.py", line 295, in _handle_request_noblock
    self.process_request(request, client_address)
  File "/usr/lib64/python2.7/SocketServer.py", line 322, in process_request
    self.shutdown_request(request)
  File "/usr/lib64/python2.7/SocketServer.py", line 475, in shutdown_request
    except socket.error:
AttributeError: 'NoneType' object has no attribute 'error'
----------------------------------------

